Workbook

Sheet Sheet1
A1: project | B1: input1 | C1: input2 | D1: input3 | E1: input4 | F1: input5 | G1: process1 | H1: process2 | I1: process3 | J1: output_new1 | K1: output_new2 | L1: output_new3 | M1: output_recycle1 | N1: output_recycle2 | O1: start_time | P1: end_time | Q1: strategy1 | R1: strategy2 | S1: strategy3 | T1: strategy4 | U1: strategy5 | V1: strategy6 | W1: strategy7 | X1: strategy8 | Y1: strategy9 | Z1: strategy10 | AA1: strategy11 | AB1: strategy12 | AC1: strategy13 | AD1: strategy14 | AE1: strategy15 | AF1: strategy16 | AG1: strategy17 | AH1: strategy18 | AI1: strategy19 | AJ1: strategy20
A2: P1 | B2: R1 | C2: R2 | D2: R3 | E2: R4 | F2: R5 | G2: T1 | H2: T2 | I2: T10 | J2: N1 | K2: N2 | L2: N3 | M2: 0 | N2: 0 | O2: 1 | P2: 2 | Q2: =[1]Sheet!A2*Sheet2!A$1 -> 0 | R2: =[1]Sheet!B2*Sheet2!B$1 -> 0 | S2: =[1]Sheet!C2*Sheet2!C$1 -> 3 | T2: =[1]Sheet!D2*Sheet2!D$1 -> 0 | U2: =[1]Sheet!E2*Sheet2!E$1 -> 0 | V2: =[1]Sheet!F2*Sheet2!F$1 -> 0 | W2: =[1]Sheet!G2*Sheet2!G$1 -> 0 | X2: =[1]Sheet!H2*Sheet2!H$1 -> 8 | ... AJ2: =[1]Sheet!T2*Sheet2!T$1 -> 0
A3: P2 | B3: R6 | C3: R7 | D3: R8 | E3: R9 | F3: R10 | G3: T4 | H3: T5 | I3: T6 | J3: N4 | K3: N5 | L3: N6 | M3: 0 | N3: 0 | O3: 1 | P3: 3 | Q3: =[1]Sheet!A3*Sheet2!A$1 -> 1 | R3: =[1]Sheet!B3*Sheet2!B$1 -> 0 | S3: =[1]Sheet!C3*Sheet2!C$1 -> 0 | T3: =[1]Sheet!D3*Sheet2!D$1 -> 0 | U3: =[1]Sheet!E3*Sheet2!E$1 -> 0 | V3: =[1]Sheet!F3*Sheet2!F$1 -> 0 | W3: =[1]Sheet!G3*Sheet2!G$1 -> 0 | X3: =[1]Sheet!H3*Sheet2!H$1 -> 0 | ... AJ3: =[1]Sheet!T3*Sheet2!T$1 -> 0
A4: P3 | B4: R301 | C4: R10 | D4: R303 | E4: R44 | F4: R305 | G4: T181 | H4: T182 | I4: T183 | J4: N181 | K4: N182 | L4: N183 | M4: R303 | N4: 0 | O4: 1 | P4: 2 | Q4: =[1]Sheet!A4*Sheet2!A$1 -> 0 | R4: =[1]Sheet!B4*Sheet2!B$1 -> 0 | S4: =[1]Sheet!C4*Sheet2!C$1 -> 0 | T4: =[1]Sheet!D4*Sheet2!D$1 -> 0 | U4: =[1]Sheet!E4*Sheet2!E$1 -> 0 | V4: =[1]Sheet!F4*Sheet2!F$1 -> 0 | W4: =[1]Sheet!G4*Sheet2!G$1 -> 7 | X4: =[1]Sheet!H4*Sheet2!H$1 -> 0 | ... AJ4: =[1]Sheet!T4*Sheet2!T$1 -> 0
A5: P4 | B5: R16 | C5: R17 | D5: R10 | E5: R5 | F5: R20 | G5: T10 | H5: T2 | I5: T12 | J5: N10 | K5: N11 | L5: N12 | M5: 0 | N5: 0 | O5: 1 | P5: 2 | Q5: =[1]Sheet!A5*Sheet2!A$1 -> 0 | R5: =[1]Sheet!B5*Sheet2!B$1 -> 0 | S5: =[1]Sheet!C5*Sheet2!C$1 -> 0 | T5: =[1]Sheet!D5*Sheet2!D$1 -> 0 | U5: =[1]Sheet!E5*Sheet2!E$1 -> 0 | V5: =[1]Sheet!F5*Sheet2!F$1 -> 6 | W5: =[1]Sheet!G5*Sheet2!G$1 -> 0 | X5: =[1]Sheet!H5*Sheet2!H$1 -> 8 | ... AJ5: =[1]Sheet!T5*Sheet2!T$1 -> 0
A6: P5 | B6: R21 | C6: R22 | D6: R23 | E6: R24 | F6: R25 | G6: T13 | H6: T14 | I6: T15 | J6: N13 | K6: N14 | L6: N15 | M6: 0 | N6: 0 | O6: 1 | P6: 2 | Q6: =[1]Sheet!A6*Sheet2!A$1 -> 1 | R6: =[1]Sheet!B6*Sheet2!B$1 -> 2 | S6: =[1]Sheet!C6*Sheet2!C$1 -> 0 | T6: =[1]Sheet!D6*Sheet2!D$1 -> 0 | U6: =[1]Sheet!E6*Sheet2!E$1 -> 0 | V6: =[1]Sheet!F6*Sheet2!F$1 -> 6 | W6: =[1]Sheet!G6*Sheet2!G$1 -> 0 | X6: =[1]Sheet!H6*Sheet2!H$1 -> 0 | ... AJ6: =[1]Sheet!T6*Sheet2!T$1 -> 0
A7: P6 | B7: R26 | C7: R2 | D7: R28 | E7: R29 | F7: R23 | G7: T16 | H7: T17 | I7: T18 | J7: N16 | K7: N17 | L7: N18 | M7: 0 | N7: 0 | O7: 1 | P7: 3 | Q7: =[1]Sheet!A7*Sheet2!A$1 -> 0 | R7: =[1]Sheet!B7*Sheet2!B$1 -> 2 | S7: =[1]Sheet!C7*Sheet2!C$1 -> 0 | T7: =[1]Sheet!D7*Sheet2!D$1 -> 0 | U7: =[1]Sheet!E7*Sheet2!E$1 -> 5 | V7: =[1]Sheet!F7*Sheet2!F$1 -> 0 | W7: =[1]Sheet!G7*Sheet2!G$1 -> 0 | X7: =[1]Sheet!H7*Sheet2!H$1 -> 0 | ... AJ7: =[1]Sheet!T7*Sheet2!T$1 -> 20
A8: P7 | B8: R31 | C8: R32 | D8: R33 | E8: R34 | F8: R35 | G8: T19 | H8: T20 | I8: T21 | J8: N19 | K8: N20 | L8: N21 | M8: 0 | N8: 0 | O8: 1 | P8: 2 | Q8: =[1]Sheet!A8*Sheet2!A$1 -> 0 | R8: =[1]Sheet!B8*Sheet2!B$1 -> 0 | S8: =[1]Sheet!C8*Sheet2!C$1 -> 0 | T8: =[1]Sheet!D8*Sheet2!D$1 -> 0 | U8: =[1]Sheet!E8*Sheet2!E$1 -> 0 | V8: =[1]Sheet!F8*Sheet2!F$1 -> 0 | W8: =[1]Sheet!G8*Sheet2!G$1 -> 0 | X8: =[1]Sheet!H8*Sheet2!H$1 -> 0 | ... AJ8: =[1]Sheet!T8*Sheet2!T$1 -> 0
A9: P8 | B9: R36 | C9: R37 | D9: R38 | E9: R16 | F9: R40 | G9: T22 | H9: T23 | I9: T24 | J9: N22 | K9: N23 | L9: N24 | M9: 0 | N9: R42 | O9: 1 | P9: 2 | Q9: =[1]Sheet!A9*Sheet2!A$1 -> 0 | R9: =[1]Sheet!B9*Sheet2!B$1 -> 0 | S9: =[1]Sheet!C9*Sheet2!C$1 -> 0 | T9: =[1]Sheet!D9*Sheet2!D$1 -> 0 | U9: =[1]Sheet!E9*Sheet2!E$1 -> 0 | V9: =[1]Sheet!F9*Sheet2!F$1 -> 0 | W9: =[1]Sheet!G9*Sheet2!G$1 -> 7 | X9: =[1]Sheet!H9*Sheet2!H$1 -> 0 | ... AJ9: =[1]Sheet!T9*Sheet2!T$1 -> 0
A10: P9 | B10: R41 | C10: R42 | D10: R23 | E10: R44 | F10: R45 | G10: T25 | H10: T26 | I10: T27 | J10: N25 | K10: N26 | L10: N27 | M10: 0 | N10: 0 | O10: 1 | P10: 2 | Q10: =[1]Sheet!A10*Sheet2!A$1 -> 0 | R10: =[1]Sheet!B10*Sheet2!B$1 -> 0 | S10: =[1]Sheet!C10*Sheet2!C$1 -> 0 | T10: =[1]Sheet!D10*Sheet2!D$1 -> 0 | U10: =[1]Sheet!E10*Sheet2!E$1 -> 0 | V10: =[1]Sheet!F10*Sheet2!F$1 -> 0 | W10: =[1]Sheet!G10*Sheet2!G$1 -> 0 | X10: =[1]Sheet!H10*Sheet2!H$1 -> 8 | ... AJ10: =[1]Sheet!T10*Sheet2!T$1 -> 0
A11: P10 | B11: R46 | C11: R47 | D11: R48 | E11: R49 | F11: R50 | G11: T28 | H11: T29 | I11: T30 | J11: N28 | K11: N29 | L11: N30 | M11: 0 | N11: 0 | O11: 1 | P11: 3 | Q11: =[1]Sheet!A11*Sheet2!A$1 -> 0 | R11: =[1]Sheet!B11*Sheet2!B$1 -> 2 | S11: =[1]Sheet!C11*Sheet2!C$1 -> 0 | T11: =[1]Sheet!D11*Sheet2!D$1 -> 4 | U11: =[1]Sheet!E11*Sheet2!E$1 -> 0 | V11: =[1]Sheet!F11*Sheet2!F$1 -> 0 | W11: =[1]Sheet!G11*Sheet2!G$1 -> 0 | X11: =[1]Sheet!H11*Sheet2!H$1 -> 0 | ... AJ11: =[1]Sheet!T11*Sheet2!T$1 -> 20
A12: P11 | B12: R51 | C12: R52 | D12: R53 | E12: R54 | F12: R55 | G12: T31 | H12: T32 | I12: T33 | J12: N31 | K12: N32 | L12: N33 | M12: 0 | N12: 0 | O12: 2 | P12: 4 | Q12: =[1]Sheet!A12*Sheet2!A$1 -> 0 | R12: =[1]Sheet!B12*Sheet2!B$1 -> 0 | S12: =[1]Sheet!C12*Sheet2!C$1 -> 0 | T12: =[1]Sheet!D12*Sheet2!D$1 -> 0 | U12: =[1]Sheet!E12*Sheet2!E$1 -> 5 | V12: =[1]Sheet!F12*Sheet2!F$1 -> 0 | W12: =[1]Sheet!G12*Sheet2!G$1 -> 0 | X12: =[1]Sheet!H12*Sheet2!H$1 -> 0 | ... AJ12: =[1]Sheet!T12*Sheet2!T$1 -> 0
A13: P12 | B13: T10 | C13: R57 | D13: R58 | E13: R59 | F13: R60 | G13: T34 | H13: T35 | I13: T36 | J13: N34 | K13: N35 | L13: N36 | M13: R127 | N13: 0 | O13: 2 | P13: 3 | Q13: =[1]Sheet!A13*Sheet2!A$1 -> 0 | R13: =[1]Sheet!B13*Sheet2!B$1 -> 0 | S13: =[1]Sheet!C13*Sheet2!C$1 -> 3 | T13: =[1]Sheet!D13*Sheet2!D$1 -> 0 | U13: =[1]Sheet!E13*Sheet2!E$1 -> 0 | V13: =[1]Sheet!F13*Sheet2!F$1 -> 0 | W13: =[1]Sheet!G13*Sheet2!G$1 -> 7 | X13: =[1]Sheet!H13*Sheet2!H$1 -> 0 | ... AJ13: =[1]Sheet!T13*Sheet2!T$1 -> 20
A14: P13 | B14: R61 | C14: R62 | D14: R14 | E14: R64 | F14: R65 | G14: T37 | H14: T5 | I14: T10 | J14: N37 | K14: N38 | L14: N39 | M14: 0 | N14: 0 | O14: 2 | P14: 3 | Q14: =[1]Sheet!A14*Sheet2!A$1 -> 0 | R14: =[1]Sheet!B14*Sheet2!B$1 -> 0 | S14: =[1]Sheet!C14*Sheet2!C$1 -> 0 | T14: =[1]Sheet!D14*Sheet2!D$1 -> 0 | U14: =[1]Sheet!E14*Sheet2!E$1 -> 0 | V14: =[1]Sheet!F14*Sheet2!F$1 -> 6 | W14: =[1]Sheet!G14*Sheet2!G$1 -> 0 | X14: =[1]Sheet!H14*Sheet2!H$1 -> 8 | ... AJ14: =[1]Sheet!T14*Sheet2!T$1 -> 20
A15: P14 | B15: R66 | C15: R67 | D15: R68 | E15: R69 | F15: R70 | G15: T40 | H15: T41 | I15: T42 | J15: N40 | K15: N41 | L15: N42 | M15: 0 | N15: 0 | O15: 2 | P15: 3 | Q15: =[1]Sheet!A15*Sheet2!A$1 -> 0 | R15: =[1]Sheet!B15*Sheet2!B$1 -> 0 | S15: =[1]Sheet!C15*Sheet2!C$1 -> 0 | T15: =[1]Sheet!D15*Sheet2!D$1 -> 0 | U15: =[1]Sheet!E15*Sheet2!E$1 -> 0 | V15: =[1]Sheet!F15*Sheet2!F$1 -> 6 | W15: =[1]Sheet!G15*Sheet2!G$1 -> 0 | X15: =[1]Sheet!H15*Sheet2!H$1 -> 0 | ... AJ15: =[1]Sheet!T15*Sheet2!T$1 -> 0
A16: P15 | B16: R14 | C16: R72 | D16: T35 | E16: R74 | F16: N12 | G16: T43 | H16: T44 | I16: T45 | J16: N43 | K16: N44 | L16: N45 | M16: 0 | N16: 0 | O16: 2 | P16: 3 | Q16: =[1]Sheet!A16*Sheet2!A$1 -> 0 | R16: =[1]Sheet!B16*Sheet2!B$1 -> 0 | S16: =[1]Sheet!C16*Sheet2!C$1 -> 3 | T16: =[1]Sheet!D16*Sheet2!D$1 -> 0 | U16: =[1]Sheet!E16*Sheet2!E$1 -> 0 | V16: =[1]Sheet!F16*Sheet2!F$1 -> 0 | W16: =[1]Sheet!G16*Sheet2!G$1 -> 0 | X16: =[1]Sheet!H16*Sheet2!H$1 -> 8 | ... AJ16: =[1]Sheet!T16*Sheet2!T$1 -> 0
A17: P16 | B17: R306 | C17: R69 | D17: R308 | E17: R309 | F17: R310 | G17: T184 | H17: T185 | I17: T186 | J17: N184 | K17: N185 | L17: N186 | M17: R80 | N17: 0 | O17: 2 | P17: 4 | Q17: =[1]Sheet!A17*Sheet2!A$1 -> 1 | R17: =[1]Sheet!B17*Sheet2!B$1 -> 0 | S17: =[1]Sheet!C17*Sheet2!C$1 -> 3 | T17: =[1]Sheet!D17*Sheet2!D$1 -> 0 | U17: =[1]Sheet!E17*Sheet2!E$1 -> 0 | V17: =[1]Sheet!F17*Sheet2!F$1 -> 0 | W17: =[1]Sheet!G17*Sheet2!G$1 -> 0 | X17: =[1]Sheet!H17*Sheet2!H$1 -> 0 | ... AJ17: =[1]Sheet!T17*Sheet2!T$1 -> 0
A18: P17 | B18: R81 | C18: R167 | D18: R83 | E18: R84 | F18: R85 | G18: T49 | H18: T50 | I18: T51 | J18: N49 | K18: N50 | L18: N51 | M18: 0 | N18: 0 | O18: 2 | P18: 4 | Q18: =[1]Sheet!A18*Sheet2!A$1 -> 0 | R18: =[1]Sheet!B18*Sheet2!B$1 -> 0 | S18: =[1]Sheet!C18*Sheet2!C$1 -> 0 | T18: =[1]Sheet!D18*Sheet2!D$1 -> 0 | U18: =[1]Sheet!E18*Sheet2!E$1 -> 0 | V18: =[1]Sheet!F18*Sheet2!F$1 -> 0 | W18: =[1]Sheet!G18*Sheet2!G$1 -> 0 | X18: =[1]Sheet!H18*Sheet2!H$1 -> 8 | ... AJ18: =[1]Sheet!T18*Sheet2!T$1 -> 0
A19: P18 | B19: N6 | C19: R87 | D19: R88 | E19: R89 | F19: R90 | G19: T52 | H19: T8 | I19: T54 | J19: N52 | K19: N53 | L19: N54 | M19: 0 | N19: R139 | O19: 2 | P19: 3 | Q19: =[1]Sheet!A19*Sheet2!A$1 -> 0 | R19: =[1]Sheet!B19*Sheet2!B$1 -> 0 | S19: =[1]Sheet!C19*Sheet2!C$1 -> 3 | T19: =[1]Sheet!D19*Sheet2!D$1 -> 0 | U19: =[1]Sheet!E19*Sheet2!E$1 -> 0 | V19: =[1]Sheet!F19*Sheet2!F$1 -> 0 | W19: =[1]Sheet!G19*Sheet2!G$1 -> 0 | X19: =[1]Sheet!H19*Sheet2!H$1 -> 8 | ... AJ19: =[1]Sheet!T19*Sheet2!T$1 -> 20
A20: P19 | B20: T14 | C20: R131 | D20: R153 | E20: T27 | F20: R167 | G20: T55 | H20: T56 | I20: T57 | J20: N55 | K20: N56 | L20: N57 | M20: R127 | N20: 0 | O20: 2 | P20: 4 | Q20: =[1]Sheet!A20*Sheet2!A$1 -> 0 | R20: =[1]Sheet!B20*Sheet2!B$1 -> 0 | S20: =[1]Sheet!C20*Sheet2!C$1 -> 0 | T20: =[1]Sheet!D20*Sheet2!D$1 -> 0 | U20: =[1]Sheet!E20*Sheet2!E$1 -> 0 | V20: =[1]Sheet!F20*Sheet2!F$1 -> 0 | W20: =[1]Sheet!G20*Sheet2!G$1 -> 0 | X20: =[1]Sheet!H20*Sheet2!H$1 -> 0 | ... AJ20: =[1]Sheet!T20*Sheet2!T$1 -> 0
A21: P20 | B21: R96 | C21: R179 | D21: R98 | E21: R99 | F21: R100 | G21: T5 | H21: T59 | I21: T60 | J21: N58 | K21: N59 | L21: N60 | M21: 0 | N21: 0 | O21: 2 | P21: 3 | Q21: =[1]Sheet!A21*Sheet2!A$1 -> 1 | R21: =[1]Sheet!B21*Sheet2!B$1 -> 0 | S21: =[1]Sheet!C21*Sheet2!C$1 -> 0 | T21: =[1]Sheet!D21*Sheet2!D$1 -> 0 | U21: =[1]Sheet!E21*Sheet2!E$1 -> 0 | V21: =[1]Sheet!F21*Sheet2!F$1 -> 0 | W21: =[1]Sheet!G21*Sheet2!G$1 -> 0 | X21: =[1]Sheet!H21*Sheet2!H$1 -> 8 | ... AJ21: =[1]Sheet!T21*Sheet2!T$1 -> 0
A22: P21 | B22: R101 | C22: R102 | D22: R103 | E22: R104 | F22: R105 | G22: T61 | H22: T2 | I22: T63 | J22: N61 | K22: N62 | L22: N63 | M22: 0 | N22: 0 | O22: 2 | P22: 3 | Q22: =[1]Sheet!A22*Sheet2!A$1 -> 0 | R22: =[1]Sheet!B22*Sheet2!B$1 -> 2 | S22: =[1]Sheet!C22*Sheet2!C$1 -> 3 | T22: =[1]Sheet!D22*Sheet2!D$1 -> 0 | U22: =[1]Sheet!E22*Sheet2!E$1 -> 5 | V22: =[1]Sheet!F22*Sheet2!F$1 -> 0 | W22: =[1]Sheet!G22*Sheet2!G$1 -> 0 | X22: =[1]Sheet!H22*Sheet2!H$1 -> 0 | ... AJ22: =[1]Sheet!T22*Sheet2!T$1 -> 0
A23: P22 | B23: T31 | C23: R107 | D23: R108 | E23: R109 | F23: R110 | G23: T64 | H23: T65 | I23: T29 | J23: N64 | K23: N65 | L23: N66 | M23: 0 | N23: 0 | O23: 2 | P23: 3 | Q23: =[1]Sheet!A23*Sheet2!A$1 -> 0 | R23: =[1]Sheet!B23*Sheet2!B$1 -> 0 | S23: =[1]Sheet!C23*Sheet2!C$1 -> 0 | T23: =[1]Sheet!D23*Sheet2!D$1 -> 0 | U23: =[1]Sheet!E23*Sheet2!E$1 -> 0 | V23: =[1]Sheet!F23*Sheet2!F$1 -> 0 | W23: =[1]Sheet!G23*Sheet2!G$1 -> 0 | X23: =[1]Sheet!H23*Sheet2!H$1 -> 8 | ... AJ23: =[1]Sheet!T23*Sheet2!T$1 -> 20
A24: P23 | B24: R111 | C24: R112 | D24: T9 | E24: R114 | F24: N18 | G24: T67 | H24: T68 | I24: T69 | J24: N67 | K24: N68 | L24: N69 | M24: 0 | N24: 0 | O24: 2 | P24: 3 | Q24: =[1]Sheet!A24*Sheet2!A$1 -> 0 | R24: =[1]Sheet!B24*Sheet2!B$1 -> 0 | S24: =[1]Sheet!C24*Sheet2!C$1 -> 0 | T24: =[1]Sheet!D24*Sheet2!D$1 -> 0 | U24: =[1]Sheet!E24*Sheet2!E$1 -> 0 | V24: =[1]Sheet!F24*Sheet2!F$1 -> 0 | W24: =[1]Sheet!G24*Sheet2!G$1 -> 7 | X24: =[1]Sheet!H24*Sheet2!H$1 -> 0 | ... AJ24: =[1]Sheet!T24*Sheet2!T$1 -> 20
A25: P24 | B25: R116 | C25: R117 | D25: R118 | E25: R119 | F25: R120 | G25: T70 | H25: T71 | I25: T72 | J25: N70 | K25: N71 | L25: N72 | M25: 0 | N25: 0 | O25: 2 | P25: 3 | Q25: =[1]Sheet!A25*Sheet2!A$1 -> 0 | R25: =[1]Sheet!B25*Sheet2!B$1 -> 0 | S25: =[1]Sheet!C25*Sheet2!C$1 -> 0 | T25: =[1]Sheet!D25*Sheet2!D$1 -> 4 | U25: =[1]Sheet!E25*Sheet2!E$1 -> 0 | V25: =[1]Sheet!F25*Sheet2!F$1 -> 0 | W25: =[1]Sheet!G25*Sheet2!G$1 -> 0 | X25: =[1]Sheet!H25*Sheet2!H$1 -> 0 | ... AJ25: =[1]Sheet!T25*Sheet2!T$1 -> 0
A26: P25 | B26: R121 | C26: R122 | D26: R123 | E26: R124 | F26: N11 | G26: T73 | H26: T5 | I26: T14 | J26: N73 | K26: N12 | L26: N75 | M26: 0 | N26: R159 | O26: 2 | P26: 4 | Q26: =[1]Sheet!A26*Sheet2!A$1 -> 1 | R26: =[1]Sheet!B26*Sheet2!B$1 -> 0 | S26: =[1]Sheet!C26*Sheet2!C$1 -> 0 | T26: =[1]Sheet!D26*Sheet2!D$1 -> 4 | U26: =[1]Sheet!E26*Sheet2!E$1 -> 0 | V26: =[1]Sheet!F26*Sheet2!F$1 -> 0 | W26: =[1]Sheet!G26*Sheet2!G$1 -> 0 | X26: =[1]Sheet!H26*Sheet2!H$1 -> 0 | ... AJ26: =[1]Sheet!T26*Sheet2!T$1 -> 20
A27: P26 | B27: R126 | C27: R127 | D27: R128 | E27: R129 | F27: R130 | G27: T76 | H27: T77 | I27: T78 | J27: N76 | K27: N77 | L27: N78 | M27: 0 | N27: 0 | O27: 2 | P27: 3 | Q27: =[1]Sheet!A27*Sheet2!A$1 -> 0 | R27: =[1]Sheet!B27*Sheet2!B$1 -> 0 | S27: =[1]Sheet!C27*Sheet2!C$1 -> 0 | T27: =[1]Sheet!D27*Sheet2!D$1 -> 0 | U27: =[1]Sheet!E27*Sheet2!E$1 -> 0 | V27: =[1]Sheet!F27*Sheet2!F$1 -> 0 | W27: =[1]Sheet!G27*Sheet2!G$1 -> 0 | X27: =[1]Sheet!H27*Sheet2!H$1 -> 0 | ... AJ27: =[1]Sheet!T27*Sheet2!T$1 -> 0
A28: P27 | B28: R131 | C28: R132 | D28: R133 | E28: R134 | F28: R186 | G28: T79 | H28: T80 | I28: T81 | J28: N79 | K28: N80 | L28: N81 | M28: 0 | N28: 0 | O28: 2 | P28: 3 | Q28: =[1]Sheet!A28*Sheet2!A$1 -> 0 | R28: =[1]Sheet!B28*Sheet2!B$1 -> 0 | S28: =[1]Sheet!C28*Sheet2!C$1 -> 0 | T28: =[1]Sheet!D28*Sheet2!D$1 -> 0 | U28: =[1]Sheet!E28*Sheet2!E$1 -> 0 | V28: =[1]Sheet!F28*Sheet2!F$1 -> 0 | W28: =[1]Sheet!G28*Sheet2!G$1 -> 0 | X28: =[1]Sheet!H28*Sheet2!H$1 -> 0 | ... AJ28: =[1]Sheet!T28*Sheet2!T$1 -> 0
A29: P28 | B29: R136 | C29: R137 | D29: N18 | E29: R139 | F29: R140 | G29: T82 | H29: T19 | I29: T84 | J29: N82 | K29: N83 | L29: N84 | M29: 0 | N29: 0 | O29: 2 | P29: 4 | Q29: =[1]Sheet!A29*Sheet2!A$1 -> 0 | R29: =[1]Sheet!B29*Sheet2!B$1 -> 2 | S29: =[1]Sheet!C29*Sheet2!C$1 -> 3 | T29: =[1]Sheet!D29*Sheet2!D$1 -> 4 | U29: =[1]Sheet!E29*Sheet2!E$1 -> 0 | V29: =[1]Sheet!F29*Sheet2!F$1 -> 6 | W29: =[1]Sheet!G29*Sheet2!G$1 -> 0 | X29: =[1]Sheet!H29*Sheet2!H$1 -> 0 | ... AJ29: =[1]Sheet!T29*Sheet2!T$1 -> 20
A30: P29 | B30: R141 | C30: T5 | D30: N9 | E30: R144 | F30: N22 | G30: T85 | H30: T86 | I30: T87 | J30: N85 | K30: N86 | L30: N83 | M30: 0 | N30: 0 | O30: 2 | P30: 3 | Q30: =[1]Sheet!A30*Sheet2!A$1 -> 0 | R30: =[1]Sheet!B30*Sheet2!B$1 -> 0 | S30: =[1]Sheet!C30*Sheet2!C$1 -> 0 | T30: =[1]Sheet!D30*Sheet2!D$1 -> 0 | U30: =[1]Sheet!E30*Sheet2!E$1 -> 5 | V30: =[1]Sheet!F30*Sheet2!F$1 -> 0 | W30: =[1]Sheet!G30*Sheet2!G$1 -> 0 | X30: =[1]Sheet!H30*Sheet2!H$1 -> 0 | ... AJ30: =[1]Sheet!T30*Sheet2!T$1 -> 0
A31: P30 | B31: R311 | C31: N33 | D31: R313 | E31: R314 | F31: R315 | G31: T187 | H31: T188 | I31: T189 | J31: N187 | K31: N188 | L31: N189 | M31: 0 | N31: 0 | O31: 2 | P31: 5 | Q31: =[1]Sheet!A31*Sheet2!A$1 -> 0 | R31: =[1]Sheet!B31*Sheet2!B$1 -> 2 | S31: =[1]Sheet!C31*Sheet2!C$1 -> 0 | T31: =[1]Sheet!D31*Sheet2!D$1 -> 0 | U31: =[1]Sheet!E31*Sheet2!E$1 -> 0 | V31: =[1]Sheet!F31*Sheet2!F$1 -> 6 | W31: =[1]Sheet!G31*Sheet2!G$1 -> 0 | X31: =[1]Sheet!H31*Sheet2!H$1 -> 0 | ... AJ31: =[1]Sheet!T31*Sheet2!T$1 -> 0
A32: P31 | B32: R151 | C32: R152 | D32: R153 | E32: R154 | F32: R155 | G32: T91 | H32: T92 | I32: T93 | J32: N91 | K32: N92 | L32: N93 | M32: 0 | N32: 0 | O32: 2 | P32: 3 | Q32: =[1]Sheet!A32*Sheet2!A$1 -> 1 | R32: =[1]Sheet!B32*Sheet2!B$1 -> 0 | S32: =[1]Sheet!C32*Sheet2!C$1 -> 0 | T32: =[1]Sheet!D32*Sheet2!D$1 -> 0 | U32: =[1]Sheet!E32*Sheet2!E$1 -> 0 | V32: =[1]Sheet!F32*Sheet2!F$1 -> 6 | W32: =[1]Sheet!G32*Sheet2!G$1 -> 7 | X32: =[1]Sheet!H32*Sheet2!H$1 -> 0 | ... AJ32: =[1]Sheet!T32*Sheet2!T$1 -> 0
A33: P32 | B33: R193 | C33: R157 | D33: R158 | E33: R159 | F33: R160 | G33: T94 | H33: T95 | I33: T96 | J33: N94 | K33: N95 | L33: N96 | M33: 0 | N33: 0 | O33: 2 | P33: 4 | Q33: =[1]Sheet!A33*Sheet2!A$1 -> 0 | R33: =[1]Sheet!B33*Sheet2!B$1 -> 0 | S33: =[1]Sheet!C33*Sheet2!C$1 -> 0 | T33: =[1]Sheet!D33*Sheet2!D$1 -> 0 | U33: =[1]Sheet!E33*Sheet2!E$1 -> 0 | V33: =[1]Sheet!F33*Sheet2!F$1 -> 0 | W33: =[1]Sheet!G33*Sheet2!G$1 -> 0 | X33: =[1]Sheet!H33*Sheet2!H$1 -> 0 | ... AJ33: =[1]Sheet!T33*Sheet2!T$1 -> 20
A34: P33 | B34: R161 | C34: R162 | D34: N27 | E34: R164 | F34: R186 | G34: T97 | H34: T98 | I34: T99 | J34: N97 | K34: N98 | L34: N99 | M34: 0 | N34: 0 | O34: 2 | P34: 5 | Q34: =[1]Sheet!A34*Sheet2!A$1 -> 1 | R34: =[1]Sheet!B34*Sheet2!B$1 -> 2 | S34: =[1]Sheet!C34*Sheet2!C$1 -> 0 | T34: =[1]Sheet!D34*Sheet2!D$1 -> 0 | U34: =[1]Sheet!E34*Sheet2!E$1 -> 0 | V34: =[1]Sheet!F34*Sheet2!F$1 -> 0 | W34: =[1]Sheet!G34*Sheet2!G$1 -> 7 | X34: =[1]Sheet!H34*Sheet2!H$1 -> 0 | ... AJ34: =[1]Sheet!T34*Sheet2!T$1 -> 0
A35: P34 | B35: N19 | C35: R167 | D35: R168 | E35: R169 | F35: R170 | G35: T100 | H35: T101 | I35: T102 | J35: N100 | K35: N101 | L35: N102 | M35: 0 | N35: 0 | O35: 2 | P35: 3 | Q35: =[1]Sheet!A35*Sheet2!A$1 -> 0 | R35: =[1]Sheet!B35*Sheet2!B$1 -> 0 | S35: =[1]Sheet!C35*Sheet2!C$1 -> 0 | T35: =[1]Sheet!D35*Sheet2!D$1 -> 0 | U35: =[1]Sheet!E35*Sheet2!E$1 -> 0 | V35: =[1]Sheet!F35*Sheet2!F$1 -> 0 | W35: =[1]Sheet!G35*Sheet2!G$1 -> 0 | X35: =[1]Sheet!H35*Sheet2!H$1 -> 0 | ... AJ35: =[1]Sheet!T35*Sheet2!T$1 -> 20
A36: P35 | B36: R316 | C36: N96 | D36: R318 | E36: R319 | F36: R320 | G36: T190 | H36: T191 | I36: T192 | J36: N190 | K36: N191 | L36: N192 | M36: 0 | N36: 0 | O36: 2 | P36: 3 | Q36: =[1]Sheet!A36*Sheet2!A$1 -> 0 | R36: =[1]Sheet!B36*Sheet2!B$1 -> 2 | S36: =[1]Sheet!C36*Sheet2!C$1 -> 0 | T36: =[1]Sheet!D36*Sheet2!D$1 -> 0 | U36: =[1]Sheet!E36*Sheet2!E$1 -> 0 | V36: =[1]Sheet!F36*Sheet2!F$1 -> 0 | W36: =[1]Sheet!G36*Sheet2!G$1 -> 0 | X36: =[1]Sheet!H36*Sheet2!H$1 -> 8 | ... AJ36: =[1]Sheet!T36*Sheet2!T$1 -> 20
A37: P36 | B37: N10 | C37: R177 | D37: T18 | E37: R179 | F37: R140 | G37: T106 | H37: T9 | I37: T108 | J37: N106 | K37: N107 | L37: N108 | M37: 0 | N37: R177 | O37: 2 | P37: 3 | Q37: =[1]Sheet!A37*Sheet2!A$1 -> 0 | R37: =[1]Sheet!B37*Sheet2!B$1 -> 2 | S37: =[1]Sheet!C37*Sheet2!C$1 -> 0 | T37: =[1]Sheet!D37*Sheet2!D$1 -> 0 | U37: =[1]Sheet!E37*Sheet2!E$1 -> 0 | V37: =[1]Sheet!F37*Sheet2!F$1 -> 0 | W37: =[1]Sheet!G37*Sheet2!G$1 -> 0 | X37: =[1]Sheet!H37*Sheet2!H$1 -> 0 | ... AJ37: =[1]Sheet!T37*Sheet2!T$1 -> 20
A38: P37 | B38: R181 | C38: R182 | D38: R183 | E38: R153 | F38: R185 | G38: T109 | H38: T110 | I38: T111 | J38: N109 | K38: N110 | L38: N111 | M38: 0 | N38: 0 | O38: 2 | P38: 3 | Q38: =[1]Sheet!A38*Sheet2!A$1 -> 0 | R38: =[1]Sheet!B38*Sheet2!B$1 -> 2 | S38: =[1]Sheet!C38*Sheet2!C$1 -> 0 | T38: =[1]Sheet!D38*Sheet2!D$1 -> 0 | U38: =[1]Sheet!E38*Sheet2!E$1 -> 0 | V38: =[1]Sheet!F38*Sheet2!F$1 -> 0 | W38: =[1]Sheet!G38*Sheet2!G$1 -> 0 | X38: =[1]Sheet!H38*Sheet2!H$1 -> 8 | ... AJ38: =[1]Sheet!T38*Sheet2!T$1 -> 20
A39: P38 | B39: R186 | C39: R187 | D39: R188 | E39: R189 | F39: R14 | G39: T112 | H39: T113 | I39: T114 | J39: N112 | K39: N113 | L39: N114 | M39: 0 | N39: 0 | O39: 2 | P39: 3 | Q39: =[1]Sheet!A39*Sheet2!A$1 -> 0 | R39: =[1]Sheet!B39*Sheet2!B$1 -> 0 | S39: =[1]Sheet!C39*Sheet2!C$1 -> 0 | T39: =[1]Sheet!D39*Sheet2!D$1 -> 0 | U39: =[1]Sheet!E39*Sheet2!E$1 -> 5 | V39: =[1]Sheet!F39*Sheet2!F$1 -> 6 | W39: =[1]Sheet!G39*Sheet2!G$1 -> 0 | X39: =[1]Sheet!H39*Sheet2!H$1 -> 8 | ... AJ39: =[1]Sheet!T39*Sheet2!T$1 -> 20
A40: P39 | B40: R140 | C40: R192 | D40: R193 | E40: R194 | F40: R9 | G40: T115 | H40: T116 | I40: T117 | J40: N115 | K40: N116 | L40: N117 | M40: 0 | N40: 0 | O40: 2 | P40: 3 | Q40: =[1]Sheet!A40*Sheet2!A$1 -> 1 | R40: =[1]Sheet!B40*Sheet2!B$1 -> 0 | S40: =[1]Sheet!C40*Sheet2!C$1 -> 3 | T40: =[1]Sheet!D40*Sheet2!D$1 -> 0 | U40: =[1]Sheet!E40*Sheet2!E$1 -> 0 | V40: =[1]Sheet!F40*Sheet2!F$1 -> 0 | W40: =[1]Sheet!G40*Sheet2!G$1 -> 0 | X40: =[1]Sheet!H40*Sheet2!H$1 -> 0 | ... AJ40: =[1]Sheet!T40*Sheet2!T$1 -> 20
...

Sheet Sheet2
A1: 1 | B1: 2 | C1: 3 | D1: 4 | E1: 5 | F1: 6 | G1: 7 | H1: 8 | I1: 9 | J1: 10 | K1: 11 | L1: 12 | M1: 13 | N1: 14 | O1: 15 | P1: 16 | Q1: 17 | R1: 18 | S1: 19 | T1: 20
