Workbook

Sheet Sheet1
A2: =IF(Sheet2!A2>=0.99,Sheet2!A2,0) -> 0 | B2: =IF(Sheet2!B2>=0.99,Sheet2!B2,0) -> 0 | C2: =IF(Sheet2!C2>=0.99,Sheet2!C2,0) -> 0.99659967 | D2: =IF(Sheet2!D2>=0.99,Sheet2!D2,0) -> 0 | E2: =IF(Sheet2!E2>=0.99,Sheet2!E2,0) -> 0 | F2: =IF(Sheet2!F2>=0.99,Sheet2!F2,0) -> 0 | G2: =IF(Sheet2!G2>=0.99,Sheet2!G2,0) -> 0 | H2: =IF(Sheet2!H2>=0.99,Sheet2!H2,0) -> 0.99299511 | ... T2: =IF(Sheet2!T2>=0.99,Sheet2!T2,0) -> 0
A3: =IF(Sheet2!A3>=0.99,Sheet2!A3,0) -> 0.99033606 | B3: =IF(Sheet2!B3>=0.99,Sheet2!B3,0) -> 0 | C3: =IF(Sheet2!C3>=0.99,Sheet2!C3,0) -> 0 | D3: =IF(Sheet2!D3>=0.99,Sheet2!D3,0) -> 0 | E3: =IF(Sheet2!E3>=0.99,Sheet2!E3,0) -> 0 | F3: =IF(Sheet2!F3>=0.99,Sheet2!F3,0) -> 0 | G3: =IF(Sheet2!G3>=0.99,Sheet2!G3,0) -> 0 | H3: =IF(Sheet2!H3>=0.99,Sheet2!H3,0) -> 0 | ... T3: =IF(Sheet2!T3>=0.99,Sheet2!T3,0) -> 0
A4: =IF(Sheet2!A4>=0.99,Sheet2!A4,0) -> 0 | B4: =IF(Sheet2!B4>=0.99,Sheet2!B4,0) -> 0 | C4: 0 | D4: =IF(Sheet2!D4>=0.99,Sheet2!D4,0) -> 0 | E4: =IF(Sheet2!E4>=0.99,Sheet2!E4,0) -> 0 | F4: =IF(Sheet2!F4>=0.99,Sheet2!F4,0) -> 0 | G4: =IF(Sheet2!G4>=0.99,Sheet2!G4,0) -> 0.99279912 | H4: =IF(Sheet2!H4>=0.99,Sheet2!H4,0) -> 0 | I4: =IF(Sheet2!I4>=0.99,Sheet2!I4,0) -> 0 | J4: 0 | K4: =IF(Sheet2!K4>=0.99,Sheet2!K4,0) -> 0 | L4: =IF(Sheet2!L4>=0.99,Sheet2!L4,0) -> 0 | M4: =IF(Sheet2!M4>=0.99,Sheet2!M4,0) -> 0 | N4: =IF(Sheet2!N4>=0.99,Sheet2!N4,0) -> 0 | O4: =IF(Sheet2!O4>=0.99,Sheet2!O4,0) -> 0 | P4: =IF(Sheet2!P4>=0.99,Sheet2!P4,0) -> 0 | Q4: =IF(Sheet2!Q4>=0.99,Sheet2!Q4,0) -> 0 | R4: =IF(Sheet2!R4>=0.99,Sheet2!R4,0) -> 0 | ... T4: =IF(Sheet2!T4>=0.99,Sheet2!T4,0) -> 0
A5: =IF(Sheet2!A5>=0.99,Sheet2!A5,0) -> 0 | B5: =IF(Sheet2!B5>=0.99,Sheet2!B5,0) -> 0 | C5: =IF(Sheet2!C5>=0.99,Sheet2!C5,0) -> 0 | D5: =IF(Sheet2!D5>=0.99,Sheet2!D5,0) -> 0 | E5: =IF(Sheet2!E5>=0.99,Sheet2!E5,0) -> 0 | F5: =IF(Sheet2!F5>=0.99,Sheet2!F5,0) -> 0.99765983 | G5: =IF(Sheet2!G5>=0.99,Sheet2!G5,0) -> 0 | H5: =IF(Sheet2!H5>=0.99,Sheet2!H5,0) -> 0.99265002 | ... T5: =IF(Sheet2!T5>=0.99,Sheet2!T5,0) -> 0
A6: =IF(Sheet2!A6>=0.99,Sheet2!A6,0) -> 0.99961257 | B6: =IF(Sheet2!B6>=0.99,Sheet2!B6,0) -> 0.99499793 | C6: =IF(Sheet2!C6>=0.99,Sheet2!C6,0) -> 0 | D6: =IF(Sheet2!D6>=0.99,Sheet2!D6,0) -> 0 | E6: =IF(Sheet2!E6>=0.99,Sheet2!E6,0) -> 0 | F6: =IF(Sheet2!F6>=0.99,Sheet2!F6,0) -> 0.99261234 | G6: =IF(Sheet2!G6>=0.99,Sheet2!G6,0) -> 0 | H6: =IF(Sheet2!H6>=0.99,Sheet2!H6,0) -> 0 | ... T6: =IF(Sheet2!T6>=0.99,Sheet2!T6,0) -> 0
A7: =IF(Sheet2!A7>=0.99,Sheet2!A7,0) -> 0 | B7: =IF(Sheet2!B7>=0.99,Sheet2!B7,0) -> 0.99134448 | C7: =IF(Sheet2!C7>=0.99,Sheet2!C7,0) -> 0 | D7: =IF(Sheet2!D7>=0.99,Sheet2!D7,0) -> 0 | E7: =IF(Sheet2!E7>=0.99,Sheet2!E7,0) -> 0.99453101 | F7: =IF(Sheet2!F7>=0.99,Sheet2!F7,0) -> 0 | G7: =IF(Sheet2!G7>=0.99,Sheet2!G7,0) -> 0 | H7: =IF(Sheet2!H7>=0.99,Sheet2!H7,0) -> 0 | ... T7: =IF(Sheet2!T7>=0.99,Sheet2!T7,0) -> 0.99994459
A8: =IF(Sheet2!A8>=0.99,Sheet2!A8,0) -> 0 | B8: =IF(Sheet2!B8>=0.99,Sheet2!B8,0) -> 0 | C8: =IF(Sheet2!C8>=0.99,Sheet2!C8,0) -> 0 | D8: =IF(Sheet2!D8>=0.99,Sheet2!D8,0) -> 0 | E8: =IF(Sheet2!E8>=0.99,Sheet2!E8,0) -> 0 | F8: =IF(Sheet2!F8>=0.99,Sheet2!F8,0) -> 0 | G8: =IF(Sheet2!G8>=0.99,Sheet2!G8,0) -> 0 | H8: =IF(Sheet2!H8>=0.99,Sheet2!H8,0) -> 0 | ... T8: =IF(Sheet2!T8>=0.99,Sheet2!T8,0) -> 0
A9: =IF(Sheet2!A9>=0.99,Sheet2!A9,0) -> 0 | B9: =IF(Sheet2!B9>=0.99,Sheet2!B9,0) -> 0 | C9: =IF(Sheet2!C9>=0.99,Sheet2!C9,0) -> 0 | D9: =IF(Sheet2!D9>=0.99,Sheet2!D9,0) -> 0 | E9: =IF(Sheet2!E9>=0.99,Sheet2!E9,0) -> 0 | F9: =IF(Sheet2!F9>=0.99,Sheet2!F9,0) -> 0 | G9: =IF(Sheet2!G9>=0.99,Sheet2!G9,0) -> 0.99194812 | H9: =IF(Sheet2!H9>=0.99,Sheet2!H9,0) -> 0 | ... T9: =IF(Sheet2!T9>=0.99,Sheet2!T9,0) -> 0
A10: =IF(Sheet2!A10>=0.99,Sheet2!A10,0) -> 0 | B10: =IF(Sheet2!B10>=0.99,Sheet2!B10,0) -> 0 | C10: =IF(Sheet2!C10>=0.99,Sheet2!C10,0) -> 0 | D10: =IF(Sheet2!D10>=0.99,Sheet2!D10,0) -> 0 | E10: =IF(Sheet2!E10>=0.99,Sheet2!E10,0) -> 0 | F10: =IF(Sheet2!F10>=0.99,Sheet2!F10,0) -> 0 | G10: =IF(Sheet2!G10>=0.99,Sheet2!G10,0) -> 0 | H10: =IF(Sheet2!H10>=0.99,Sheet2!H10,0) -> 0.99069482 | ... T10: =IF(Sheet2!T10>=0.99,Sheet2!T10,0) -> 0
A11: =IF(Sheet2!A11>=0.99,Sheet2!A11,0) -> 0 | B11: =IF(Sheet2!B11>=0.99,Sheet2!B11,0) -> 0.99210831 | C11: =IF(Sheet2!C11>=0.99,Sheet2!C11,0) -> 0 | D11: =IF(Sheet2!D11>=0.99,Sheet2!D11,0) -> 0.99089487 | E11: =IF(Sheet2!E11>=0.99,Sheet2!E11,0) -> 0 | F11: =IF(Sheet2!F11>=0.99,Sheet2!F11,0) -> 0 | G11: =IF(Sheet2!G11>=0.99,Sheet2!G11,0) -> 0 | H11: =IF(Sheet2!H11>=0.99,Sheet2!H11,0) -> 0 | ... T11: =IF(Sheet2!T11>=0.99,Sheet2!T11,0) -> 0.99457426
A12: =IF(Sheet2!A12>=0.99,Sheet2!A12,0) -> 0 | B12: =IF(Sheet2!B12>=0.99,Sheet2!B12,0) -> 0 | C12: =IF(Sheet2!C12>=0.99,Sheet2!C12,0) -> 0 | D12: =IF(Sheet2!D12>=0.99,Sheet2!D12,0) -> 0 | E12: =IF(Sheet2!E12>=0.99,Sheet2!E12,0) -> 0.99079613 | F12: =IF(Sheet2!F12>=0.99,Sheet2!F12,0) -> 0 | G12: =IF(Sheet2!G12>=0.99,Sheet2!G12,0) -> 0 | H12: =IF(Sheet2!H12>=0.99,Sheet2!H12,0) -> 0 | ... T12: =IF(Sheet2!T12>=0.99,Sheet2!T12,0) -> 0
A13: =IF(Sheet2!A13>=0.99,Sheet2!A13,0) -> 0 | B13: =IF(Sheet2!B13>=0.99,Sheet2!B13,0) -> 0 | C13: =IF(Sheet2!C13>=0.99,Sheet2!C13,0) -> 0.99825379 | D13: =IF(Sheet2!D13>=0.99,Sheet2!D13,0) -> 0 | E13: =IF(Sheet2!E13>=0.99,Sheet2!E13,0) -> 0 | F13: =IF(Sheet2!F13>=0.99,Sheet2!F13,0) -> 0 | G13: =IF(Sheet2!G13>=0.99,Sheet2!G13,0) -> 0.99711798 | H13: =IF(Sheet2!H13>=0.99,Sheet2!H13,0) -> 0 | ... T13: =IF(Sheet2!T13>=0.99,Sheet2!T13,0) -> 0.9973586
A14: =IF(Sheet2!A14>=0.99,Sheet2!A14,0) -> 0 | B14: =IF(Sheet2!B14>=0.99,Sheet2!B14,0) -> 0 | C14: =IF(Sheet2!C14>=0.99,Sheet2!C14,0) -> 0 | D14: =IF(Sheet2!D14>=0.99,Sheet2!D14,0) -> 0 | E14: =IF(Sheet2!E14>=0.99,Sheet2!E14,0) -> 0 | F14: =IF(Sheet2!F14>=0.99,Sheet2!F14,0) -> 0.9957835 | G14: =IF(Sheet2!G14>=0.99,Sheet2!G14,0) -> 0 | H14: =IF(Sheet2!H14>=0.99,Sheet2!H14,0) -> 0.99577074 | ... T14: =IF(Sheet2!T14>=0.99,Sheet2!T14,0) -> 0.99103727
A15: =IF(Sheet2!A15>=0.99,Sheet2!A15,0) -> 0 | B15: =IF(Sheet2!B15>=0.99,Sheet2!B15,0) -> 0 | C15: =IF(Sheet2!C15>=0.99,Sheet2!C15,0) -> 0 | D15: =IF(Sheet2!D15>=0.99,Sheet2!D15,0) -> 0 | E15: =IF(Sheet2!E15>=0.99,Sheet2!E15,0) -> 0 | F15: =IF(Sheet2!F15>=0.99,Sheet2!F15,0) -> 0.99295644 | G15: =IF(Sheet2!G15>=0.99,Sheet2!G15,0) -> 0 | H15: =IF(Sheet2!H15>=0.99,Sheet2!H15,0) -> 0 | ... T15: =IF(Sheet2!T15>=0.99,Sheet2!T15,0) -> 0
A16: =IF(Sheet2!A16>=0.99,Sheet2!A16,0) -> 0 | B16: =IF(Sheet2!B16>=0.99,Sheet2!B16,0) -> 0 | C16: =IF(Sheet2!C16>=0.99,Sheet2!C16,0) -> 0.99491669 | D16: =IF(Sheet2!D16>=0.99,Sheet2!D16,0) -> 0 | E16: =IF(Sheet2!E16>=0.99,Sheet2!E16,0) -> 0 | F16: =IF(Sheet2!F16>=0.99,Sheet2!F16,0) -> 0 | G16: =IF(Sheet2!G16>=0.99,Sheet2!G16,0) -> 0 | H16: =IF(Sheet2!H16>=0.99,Sheet2!H16,0) -> 0.99058904 | ... T16: =IF(Sheet2!T16>=0.99,Sheet2!T16,0) -> 0
A17: 0.99 | B17: 0 | C17: 0.99 | D17: =IF(Sheet2!D17>=0.99,Sheet2!D17,0) -> 0 | E17: =IF(Sheet2!E17>=0.99,Sheet2!E17,0) -> 0 | F17: =IF(Sheet2!F17>=0.99,Sheet2!F17,0) -> 0 | G17: 0 | H17: =IF(Sheet2!H17>=0.99,Sheet2!H17,0) -> 0 | I17: =IF(Sheet2!I17>=0.99,Sheet2!I17,0) -> 0 | J17: =IF(Sheet2!J17>=0.99,Sheet2!J17,0) -> 0 | K17: =IF(Sheet2!K17>=0.99,Sheet2!K17,0) -> 0 | L17: =IF(Sheet2!L17>=0.99,Sheet2!L17,0) -> 0 | M17: 1 | N17: =IF(Sheet2!N17>=0.99,Sheet2!N17,0) -> 0 | O17: =IF(Sheet2!O17>=0.99,Sheet2!O17,0) -> 0 | P17: =IF(Sheet2!P17>=0.99,Sheet2!P17,0) -> 0 | Q17: =IF(Sheet2!Q17>=0.99,Sheet2!Q17,0) -> 0 | R17: =IF(Sheet2!R17>=0.99,Sheet2!R17,0) -> 0 | S17: =IF(Sheet2!S17>=0.99,Sheet2!S17,0) -> 0 | T17: =IF(Sheet2!T17>=0.99,Sheet2!T17,0) -> 0
A18: =IF(Sheet2!A18>=0.99,Sheet2!A18,0) -> 0 | B18: =IF(Sheet2!B18>=0.99,Sheet2!B18,0) -> 0 | C18: =IF(Sheet2!C18>=0.99,Sheet2!C18,0) -> 0 | D18: =IF(Sheet2!D18>=0.99,Sheet2!D18,0) -> 0 | E18: =IF(Sheet2!E18>=0.99,Sheet2!E18,0) -> 0 | F18: =IF(Sheet2!F18>=0.99,Sheet2!F18,0) -> 0 | G18: =IF(Sheet2!G18>=0.99,Sheet2!G18,0) -> 0 | H18: =IF(Sheet2!H18>=0.99,Sheet2!H18,0) -> 0.99410675 | ... T18: =IF(Sheet2!T18>=0.99,Sheet2!T18,0) -> 0
A19: =IF(Sheet2!A19>=0.99,Sheet2!A19,0) -> 0 | B19: =IF(Sheet2!B19>=0.99,Sheet2!B19,0) -> 0 | C19: =IF(Sheet2!C19>=0.99,Sheet2!C19,0) -> 0.99184358 | D19: =IF(Sheet2!D19>=0.99,Sheet2!D19,0) -> 0 | E19: =IF(Sheet2!E19>=0.99,Sheet2!E19,0) -> 0 | F19: =IF(Sheet2!F19>=0.99,Sheet2!F19,0) -> 0 | G19: =IF(Sheet2!G19>=0.99,Sheet2!G19,0) -> 0 | H19: =IF(Sheet2!H19>=0.99,Sheet2!H19,0) -> 0.9921983 | ... T19: =IF(Sheet2!T19>=0.99,Sheet2!T19,0) -> 0.99616638
A20: =IF(Sheet2!A20>=0.99,Sheet2!A20,0) -> 0 | B20: =IF(Sheet2!B20>=0.99,Sheet2!B20,0) -> 0 | C20: =IF(Sheet2!C20>=0.99,Sheet2!C20,0) -> 0 | D20: =IF(Sheet2!D20>=0.99,Sheet2!D20,0) -> 0 | E20: =IF(Sheet2!E20>=0.99,Sheet2!E20,0) -> 0 | F20: =IF(Sheet2!F20>=0.99,Sheet2!F20,0) -> 0 | G20: =IF(Sheet2!G20>=0.99,Sheet2!G20,0) -> 0 | H20: =IF(Sheet2!H20>=0.99,Sheet2!H20,0) -> 0 | ... T20: =IF(Sheet2!T20>=0.99,Sheet2!T20,0) -> 0
A21: =IF(Sheet2!A21>=0.99,Sheet2!A21,0) -> 0.99144512 | B21: =IF(Sheet2!B21>=0.99,Sheet2!B21,0) -> 0 | C21: =IF(Sheet2!C21>=0.99,Sheet2!C21,0) -> 0 | D21: =IF(Sheet2!D21>=0.99,Sheet2!D21,0) -> 0 | E21: =IF(Sheet2!E21>=0.99,Sheet2!E21,0) -> 0 | F21: =IF(Sheet2!F21>=0.99,Sheet2!F21,0) -> 0 | G21: =IF(Sheet2!G21>=0.99,Sheet2!G21,0) -> 0 | H21: =IF(Sheet2!H21>=0.99,Sheet2!H21,0) -> 0.99412363 | ... T21: =IF(Sheet2!T21>=0.99,Sheet2!T21,0) -> 0
A22: =IF(Sheet2!A22>=0.99,Sheet2!A22,0) -> 0 | B22: =IF(Sheet2!B22>=0.99,Sheet2!B22,0) -> 0.99188421 | C22: =IF(Sheet2!C22>=0.99,Sheet2!C22,0) -> 0.99847227 | D22: =IF(Sheet2!D22>=0.99,Sheet2!D22,0) -> 0 | E22: =IF(Sheet2!E22>=0.99,Sheet2!E22,0) -> 0.9943732 | F22: =IF(Sheet2!F22>=0.99,Sheet2!F22,0) -> 0 | G22: =IF(Sheet2!G22>=0.99,Sheet2!G22,0) -> 0 | H22: =IF(Sheet2!H22>=0.99,Sheet2!H22,0) -> 0 | ... T22: =IF(Sheet2!T22>=0.99,Sheet2!T22,0) -> 0
A23: =IF(Sheet2!A23>=0.99,Sheet2!A23,0) -> 0 | B23: =IF(Sheet2!B23>=0.99,Sheet2!B23,0) -> 0 | C23: =IF(Sheet2!C23>=0.99,Sheet2!C23,0) -> 0 | D23: =IF(Sheet2!D23>=0.99,Sheet2!D23,0) -> 0 | E23: =IF(Sheet2!E23>=0.99,Sheet2!E23,0) -> 0 | F23: =IF(Sheet2!F23>=0.99,Sheet2!F23,0) -> 0 | G23: =IF(Sheet2!G23>=0.99,Sheet2!G23,0) -> 0 | H23: =IF(Sheet2!H23>=0.99,Sheet2!H23,0) -> 0.99141863 | ... T23: =IF(Sheet2!T23>=0.99,Sheet2!T23,0) -> 0.99167828
A24: =IF(Sheet2!A24>=0.99,Sheet2!A24,0) -> 0 | B24: =IF(Sheet2!B24>=0.99,Sheet2!B24,0) -> 0 | C24: =IF(Sheet2!C24>=0.99,Sheet2!C24,0) -> 0 | D24: =IF(Sheet2!D24>=0.99,Sheet2!D24,0) -> 0 | E24: =IF(Sheet2!E24>=0.99,Sheet2!E24,0) -> 0 | F24: =IF(Sheet2!F24>=0.99,Sheet2!F24,0) -> 0 | G24: =IF(Sheet2!G24>=0.99,Sheet2!G24,0) -> 0.99720803 | H24: =IF(Sheet2!H24>=0.99,Sheet2!H24,0) -> 0 | ... T24: =IF(Sheet2!T24>=0.99,Sheet2!T24,0) -> 0.99942203
A25: =IF(Sheet2!A25>=0.99,Sheet2!A25,0) -> 0 | B25: =IF(Sheet2!B25>=0.99,Sheet2!B25,0) -> 0 | C25: =IF(Sheet2!C25>=0.99,Sheet2!C25,0) -> 0 | D25: =IF(Sheet2!D25>=0.99,Sheet2!D25,0) -> 0.99799564 | E25: =IF(Sheet2!E25>=0.99,Sheet2!E25,0) -> 0 | F25: =IF(Sheet2!F25>=0.99,Sheet2!F25,0) -> 0 | G25: =IF(Sheet2!G25>=0.99,Sheet2!G25,0) -> 0 | H25: =IF(Sheet2!H25>=0.99,Sheet2!H25,0) -> 0 | ... T25: =IF(Sheet2!T25>=0.99,Sheet2!T25,0) -> 0
A26: =IF(Sheet2!A26>=0.99,Sheet2!A26,0) -> 0.99836385 | B26: =IF(Sheet2!B26>=0.99,Sheet2!B26,0) -> 0 | C26: =IF(Sheet2!C26>=0.99,Sheet2!C26,0) -> 0 | D26: =IF(Sheet2!D26>=0.99,Sheet2!D26,0) -> 0.99759111 | E26: =IF(Sheet2!E26>=0.99,Sheet2!E26,0) -> 0 | F26: =IF(Sheet2!F26>=0.99,Sheet2!F26,0) -> 0 | G26: =IF(Sheet2!G26>=0.99,Sheet2!G26,0) -> 0 | H26: =IF(Sheet2!H26>=0.99,Sheet2!H26,0) -> 0 | ... T26: =IF(Sheet2!T26>=0.99,Sheet2!T26,0) -> 0.99929252
A27: =IF(Sheet2!A27>=0.99,Sheet2!A27,0) -> 0 | B27: =IF(Sheet2!B27>=0.99,Sheet2!B27,0) -> 0 | C27: =IF(Sheet2!C27>=0.99,Sheet2!C27,0) -> 0 | D27: =IF(Sheet2!D27>=0.99,Sheet2!D27,0) -> 0 | E27: =IF(Sheet2!E27>=0.99,Sheet2!E27,0) -> 0 | F27: =IF(Sheet2!F27>=0.99,Sheet2!F27,0) -> 0 | G27: =IF(Sheet2!G27>=0.99,Sheet2!G27,0) -> 0 | H27: =IF(Sheet2!H27>=0.99,Sheet2!H27,0) -> 0 | ... T27: =IF(Sheet2!T27>=0.99,Sheet2!T27,0) -> 0
A28: =IF(Sheet2!A28>=0.99,Sheet2!A28,0) -> 0 | B28: =IF(Sheet2!B28>=0.99,Sheet2!B28,0) -> 0 | C28: =IF(Sheet2!C28>=0.99,Sheet2!C28,0) -> 0 | D28: =IF(Sheet2!D28>=0.99,Sheet2!D28,0) -> 0 | E28: =IF(Sheet2!E28>=0.99,Sheet2!E28,0) -> 0 | F28: =IF(Sheet2!F28>=0.99,Sheet2!F28,0) -> 0 | G28: =IF(Sheet2!G28>=0.99,Sheet2!G28,0) -> 0 | H28: =IF(Sheet2!H28>=0.99,Sheet2!H28,0) -> 0 | ... T28: =IF(Sheet2!T28>=0.99,Sheet2!T28,0) -> 0
A29: =IF(Sheet2!A29>=0.99,Sheet2!A29,0) -> 0 | B29: =IF(Sheet2!B29>=0.99,Sheet2!B29,0) -> 0.99770283 | C29: =IF(Sheet2!C29>=0.99,Sheet2!C29,0) -> 0.99651949 | D29: =IF(Sheet2!D29>=0.99,Sheet2!D29,0) -> 0.99032243 | E29: =IF(Sheet2!E29>=0.99,Sheet2!E29,0) -> 0 | F29: =IF(Sheet2!F29>=0.99,Sheet2!F29,0) -> 0.99169195 | G29: =IF(Sheet2!G29>=0.99,Sheet2!G29,0) -> 0 | H29: =IF(Sheet2!H29>=0.99,Sheet2!H29,0) -> 0 | ... T29: =IF(Sheet2!T29>=0.99,Sheet2!T29,0) -> 0.99060821
A30: =IF(Sheet2!A30>=0.99,Sheet2!A30,0) -> 0 | B30: =IF(Sheet2!B30>=0.99,Sheet2!B30,0) -> 0 | C30: =IF(Sheet2!C30>=0.99,Sheet2!C30,0) -> 0 | D30: =IF(Sheet2!D30>=0.99,Sheet2!D30,0) -> 0 | E30: =IF(Sheet2!E30>=0.99,Sheet2!E30,0) -> 0.99097897 | F30: =IF(Sheet2!F30>=0.99,Sheet2!F30,0) -> 0 | G30: =IF(Sheet2!G30>=0.99,Sheet2!G30,0) -> 0 | H30: =IF(Sheet2!H30>=0.99,Sheet2!H30,0) -> 0 | ... T30: =IF(Sheet2!T30>=0.99,Sheet2!T30,0) -> 0
A31: 0 | B31: 1 | C31: =IF(Sheet2!C31>=0.99,Sheet2!C31,0) -> 0 | D31: =IF(Sheet2!D31>=0.99,Sheet2!D31,0) -> 0 | E31: =IF(Sheet2!E31>=0.99,Sheet2!E31,0) -> 0 | F31: =IF(Sheet2!F31>=0.99,Sheet2!F31,0) -> 0.99996724 | G31: =IF(Sheet2!G31>=0.99,Sheet2!G31,0) -> 0 | H31: =IF(Sheet2!H31>=0.99,Sheet2!H31,0) -> 0 | I31: 0.99 | J31: =IF(Sheet2!J31>=0.99,Sheet2!J31,0) -> 0 | K31: =IF(Sheet2!K31>=0.99,Sheet2!K31,0) -> 0 | L31: =IF(Sheet2!L31>=0.99,Sheet2!L31,0) -> 0 | M31: 0 | N31: =IF(Sheet2!N31>=0.99,Sheet2!N31,0) -> 0 | O31: 0 | P31: =IF(Sheet2!P31>=0.99,Sheet2!P31,0) -> 0 | Q31: =IF(Sheet2!Q31>=0.99,Sheet2!Q31,0) -> 0.99928516 | R31: =IF(Sheet2!R31>=0.99,Sheet2!R31,0) -> 0 | S31: 1 | T31: =IF(Sheet2!T31>=0.99,Sheet2!T31,0) -> 0
A32: =IF(Sheet2!A32>=0.99,Sheet2!A32,0) -> 0.99090483 | B32: =IF(Sheet2!B32>=0.99,Sheet2!B32,0) -> 0 | C32: =IF(Sheet2!C32>=0.99,Sheet2!C32,0) -> 0 | D32: =IF(Sheet2!D32>=0.99,Sheet2!D32,0) -> 0 | E32: =IF(Sheet2!E32>=0.99,Sheet2!E32,0) -> 0 | F32: =IF(Sheet2!F32>=0.99,Sheet2!F32,0) -> 0.99552149 | G32: =IF(Sheet2!G32>=0.99,Sheet2!G32,0) -> 0.99452859 | H32: =IF(Sheet2!H32>=0.99,Sheet2!H32,0) -> 0 | ... T32: =IF(Sheet2!T32>=0.99,Sheet2!T32,0) -> 0
A33: =IF(Sheet2!A33>=0.99,Sheet2!A33,0) -> 0 | B33: =IF(Sheet2!B33>=0.99,Sheet2!B33,0) -> 0 | C33: =IF(Sheet2!C33>=0.99,Sheet2!C33,0) -> 0 | D33: =IF(Sheet2!D33>=0.99,Sheet2!D33,0) -> 0 | E33: =IF(Sheet2!E33>=0.99,Sheet2!E33,0) -> 0 | F33: =IF(Sheet2!F33>=0.99,Sheet2!F33,0) -> 0 | G33: =IF(Sheet2!G33>=0.99,Sheet2!G33,0) -> 0 | H33: =IF(Sheet2!H33>=0.99,Sheet2!H33,0) -> 0 | ... T33: =IF(Sheet2!T33>=0.99,Sheet2!T33,0) -> 0.99688547
A34: =IF(Sheet2!A34>=0.99,Sheet2!A34,0) -> 0.99177507 | B34: =IF(Sheet2!B34>=0.99,Sheet2!B34,0) -> 0.99165092 | C34: =IF(Sheet2!C34>=0.99,Sheet2!C34,0) -> 0 | D34: =IF(Sheet2!D34>=0.99,Sheet2!D34,0) -> 0 | E34: =IF(Sheet2!E34>=0.99,Sheet2!E34,0) -> 0 | F34: =IF(Sheet2!F34>=0.99,Sheet2!F34,0) -> 0 | G34: =IF(Sheet2!G34>=0.99,Sheet2!G34,0) -> 0.99362916 | H34: =IF(Sheet2!H34>=0.99,Sheet2!H34,0) -> 0 | ... T34: =IF(Sheet2!T34>=0.99,Sheet2!T34,0) -> 0
A35: =IF(Sheet2!A35>=0.99,Sheet2!A35,0) -> 0 | B35: =IF(Sheet2!B35>=0.99,Sheet2!B35,0) -> 0 | C35: =IF(Sheet2!C35>=0.99,Sheet2!C35,0) -> 0 | D35: =IF(Sheet2!D35>=0.99,Sheet2!D35,0) -> 0 | E35: =IF(Sheet2!E35>=0.99,Sheet2!E35,0) -> 0 | F35: =IF(Sheet2!F35>=0.99,Sheet2!F35,0) -> 0 | G35: =IF(Sheet2!G35>=0.99,Sheet2!G35,0) -> 0 | H35: =IF(Sheet2!H35>=0.99,Sheet2!H35,0) -> 0 | ... T35: =IF(Sheet2!T35>=0.99,Sheet2!T35,0) -> 0.99386397
A36: 0 | B36: 1 | C36: =IF(Sheet2!C36>=0.99,Sheet2!C36,0) -> 0 | D36: =IF(Sheet2!D36>=0.99,Sheet2!D36,0) -> 0 | E36: =IF(Sheet2!E36>=0.99,Sheet2!E36,0) -> 0 | F36: =IF(Sheet2!F36>=0.99,Sheet2!F36,0) -> 0 | G36: =IF(Sheet2!G36>=0.99,Sheet2!G36,0) -> 0 | H36: =IF(Sheet2!H36>=0.99,Sheet2!H36,0) -> 0.99171494 | I36: 0 | J36: =IF(Sheet2!J36>=0.99,Sheet2!J36,0) -> 0 | K36: =IF(Sheet2!K36>=0.99,Sheet2!K36,0) -> 0 | L36: =IF(Sheet2!L36>=0.99,Sheet2!L36,0) -> 0 | M36: =IF(Sheet2!M36>=0.99,Sheet2!M36,0) -> 0 | N36: 0 | O36: =IF(Sheet2!O36>=0.99,Sheet2!O36,0) -> 0 | P36: =IF(Sheet2!P36>=0.99,Sheet2!P36,0) -> 0 | Q36: 0 | R36: =IF(Sheet2!R36>=0.99,Sheet2!R36,0) -> 0 | S36: =IF(Sheet2!S36>=0.99,Sheet2!S36,0) -> 0 | T36: 1
A37: =IF(Sheet2!A37>=0.99,Sheet2!A37,0) -> 0 | B37: =IF(Sheet2!B37>=0.99,Sheet2!B37,0) -> 0.99719048 | C37: =IF(Sheet2!C37>=0.99,Sheet2!C37,0) -> 0 | D37: =IF(Sheet2!D37>=0.99,Sheet2!D37,0) -> 0 | E37: =IF(Sheet2!E37>=0.99,Sheet2!E37,0) -> 0 | F37: =IF(Sheet2!F37>=0.99,Sheet2!F37,0) -> 0 | G37: =IF(Sheet2!G37>=0.99,Sheet2!G37,0) -> 0 | H37: =IF(Sheet2!H37>=0.99,Sheet2!H37,0) -> 0 | ... T37: =IF(Sheet2!T37>=0.99,Sheet2!T37,0) -> 0.99405106
A38: =IF(Sheet2!A38>=0.99,Sheet2!A38,0) -> 0 | B38: =IF(Sheet2!B38>=0.99,Sheet2!B38,0) -> 0.99795498 | C38: =IF(Sheet2!C38>=0.99,Sheet2!C38,0) -> 0 | D38: =IF(Sheet2!D38>=0.99,Sheet2!D38,0) -> 0 | E38: =IF(Sheet2!E38>=0.99,Sheet2!E38,0) -> 0 | F38: =IF(Sheet2!F38>=0.99,Sheet2!F38,0) -> 0 | G38: =IF(Sheet2!G38>=0.99,Sheet2!G38,0) -> 0 | H38: =IF(Sheet2!H38>=0.99,Sheet2!H38,0) -> 0.99679262 | ... T38: =IF(Sheet2!T38>=0.99,Sheet2!T38,0) -> 0.9925618
A39: =IF(Sheet2!A39>=0.99,Sheet2!A39,0) -> 0 | B39: =IF(Sheet2!B39>=0.99,Sheet2!B39,0) -> 0 | C39: =IF(Sheet2!C39>=0.99,Sheet2!C39,0) -> 0 | D39: =IF(Sheet2!D39>=0.99,Sheet2!D39,0) -> 0 | E39: =IF(Sheet2!E39>=0.99,Sheet2!E39,0) -> 0.9916756 | F39: =IF(Sheet2!F39>=0.99,Sheet2!F39,0) -> 0.99559751 | G39: =IF(Sheet2!G39>=0.99,Sheet2!G39,0) -> 0 | H39: =IF(Sheet2!H39>=0.99,Sheet2!H39,0) -> 0.99847943 | ... T39: =IF(Sheet2!T39>=0.99,Sheet2!T39,0) -> 0.99615219
A40: =IF(Sheet2!A40>=0.99,Sheet2!A40,0) -> 0.99954975 | B40: =IF(Sheet2!B40>=0.99,Sheet2!B40,0) -> 0 | C40: =IF(Sheet2!C40>=0.99,Sheet2!C40,0) -> 0.99342127 | D40: =IF(Sheet2!D40>=0.99,Sheet2!D40,0) -> 0 | E40: =IF(Sheet2!E40>=0.99,Sheet2!E40,0) -> 0 | F40: =IF(Sheet2!F40>=0.99,Sheet2!F40,0) -> 0 | G40: =IF(Sheet2!G40>=0.99,Sheet2!G40,0) -> 0 | H40: =IF(Sheet2!H40>=0.99,Sheet2!H40,0) -> 0 | ... T40: =IF(Sheet2!T40>=0.99,Sheet2!T40,0) -> 0.99712608
A41: =IF(Sheet2!A41>=0.99,Sheet2!A41,0) -> 0 | B41: =IF(Sheet2!B41>=0.99,Sheet2!B41,0) -> 0.99299873 | C41: =IF(Sheet2!C41>=0.99,Sheet2!C41,0) -> 0.99097914 | D41: =IF(Sheet2!D41>=0.99,Sheet2!D41,0) -> 0 | E41: =IF(Sheet2!E41>=0.99,Sheet2!E41,0) -> 0 | F41: =IF(Sheet2!F41>=0.99,Sheet2!F41,0) -> 0.99434495 | G41: =IF(Sheet2!G41>=0.99,Sheet2!G41,0) -> 0 | H41: =IF(Sheet2!H41>=0.99,Sheet2!H41,0) -> 0.99103057 | ... T41: =IF(Sheet2!T41>=0.99,Sheet2!T41,0) -> 0
...

Sheet Sheet2
A2: 0.98835467 | B2: 0 | C2: 0.99659967 | D2: 0 | E2: 0 | F2: 0 | G2: 0 | H2: 0.99299511 | I2: 0 | J2: 0 | K2: 0 | L2: 0.98929807 | M2: 0 | N2: 0 | O2: 0 | P2: 0 | Q2: 0 | R2: 0 | S2: 0 | T2: 0
A3: 0.99033606 | B3: 0.98396892 | C3: 0 | D3: 0 | E3: 0 | F3: 0.98188445 | G3: 0 | H3: 0.98408256 | I3: 0.99952953 | J3: 0 | K3: 0.98327161 | L3: 0.99379686 | M3: 0.98341219 | N3: 0 | O3: 0 | P3: 0 | Q3: 0.98356203 | R3: 0.98911458 | S3: 0 | T3: 0
A4: 0 | B4: 0 | C4: 0.99526263 | D4: 0 | E4: 0 | F4: 0 | G4: 0.99279912 | H4: 0 | I4: 0 | J4: 0.99390786 | K4: 0 | L4: 0 | M4: 0 | N4: 0.98106045 | O4: 0 | P4: 0.98709024 | Q4: 0 | R4: 0 | S4: 0 | T4: 0
A5: 0.98390007 | B5: 0 | C5: 0 | D5: 0 | E5: 0 | F5: 0.99765983 | G5: 0 | H5: 0.99265002 | I5: 0.9904703 | J5: 0.9879763 | K5: 0 | L5: 0 | M5: 0 | N5: 0 | O5: 0 | P5: 0 | Q5: 0.98431462 | R5: 0 | S5: 0.99497108 | T5: 0
A6: 0.99961257 | B6: 0.99499793 | C6: 0 | D6: 0 | E6: 0 | F6: 0.99261234 | G6: 0.98360172 | H6: 0 | I6: 0.99460849 | J6: 0.98641873 | K6: 0.9961864 | L6: 0.98395647 | M6: 0 | N6: 0 | O6: 0 | P6: 0 | Q6: 0.98960228 | R6: 0 | S6: 0 | T6: 0
A7: 0 | B7: 0.99134448 | C7: 0.98143258 | D7: 0.98423625 | E7: 0.99453101 | F7: 0 | G7: 0 | H7: 0.98604746 | I7: 0.98752051 | J7: 0 | K7: 0.99699178 | L7: 0 | M7: 0 | N7: 0 | O7: 0.98994539 | P7: 0 | Q7: 0 | R7: 0.98000483 | S7: 0.99731829 | T7: 0.99994459
A8: 0 | B8: 0 | C8: 0 | D8: 0 | E8: 0.98122716 | F8: 0 | G8: 0.98879671 | H8: 0.98178153 | I8: 0 | J8: 0.98179508 | K8: 0.99010526 | L8: 0 | M8: 0 | N8: 0.99958094 | O8: 0 | P8: 0.99631004 | Q8: 0.98060991 | R8: 0.99775267 | S8: 0 | T8: 0
A9: 0 | B9: 0.98335273 | C9: 0 | D9: 0.98813175 | E9: 0 | F9: 0.98198901 | G9: 0.99194812 | H9: 0 | I9: 0 | J9: 0 | K9: 0.98133077 | L9: 0 | M9: 0.98449656 | N9: 0.98037557 | O9: 0 | P9: 0.98832129 | Q9: 0 | R9: 0.98542044 | S9: 0.99840897 | T9: 0
A10: 0 | B10: 0 | C10: 0.98257471 | D10: 0 | E10: 0 | F10: 0 | G10: 0 | H10: 0.99069482 | I10: 0 | J10: 0 | K10: 0 | L10: 0.99969467 | M10: 0 | N10: 0 | O10: 0 | P10: 0 | Q10: 0 | R10: 0.98195347 | S10: 0.98095105 | T10: 0
A11: 0 | B11: 0.99210831 | C11: 0 | D11: 0.99089487 | E11: 0 | F11: 0 | G11: 0.98326445 | H11: 0 | I11: 0 | J11: 0 | K11: 0 | L11: 0.99766356 | M11: 0 | N11: 0.99661709 | O11: 0 | P11: 0 | Q11: 0.98961325 | R11: 0 | S11: 0.99137027 | T11: 0.99457426
A12: 0 | B12: 0 | C12: 0 | D12: 0 | E12: 0.99079613 | F12: 0 | G12: 0.98148227 | H12: 0.98098785 | I12: 0 | J12: 0.99814892 | K12: 0 | L12: 0.99197837 | M12: 0.98446044 | N12: 0.98733686 | O12: 0.98956515 | P12: 0 | Q12: 0 | R12: 0.99478454 | S12: 0 | T12: 0.98641064
A13: 0 | B13: 0 | C13: 0.99825379 | D13: 0 | E13: 0 | F13: 0 | G13: 0.99711798 | H13: 0 | I13: 0 | J13: 0 | K13: 0 | L13: 0 | M13: 0 | N13: 0 | O13: 0.99250363 | P13: 0.99875194 | Q13: 0.98823584 | R13: 0 | S13: 0 | T13: 0.9973586
... A61: 0 | B61: 0.98067144 | C61: 0.98343569 | D61: 0.99249208 | E61: 0.98934607 | F61: 0 | G61: 0 | H61: 0.98442038 | I61: 0.98430781 | J61: 0 | K61: 0 | L61: 0 | M61: 0 | N61: 0.99174942 | O61: 0.98470947 | P61: 0.99890583 | Q61: 0.99031547 | R61: 0 | S61: 0.98687043 | T61: 0
A62: =SUM(A2:A61) -> 23.78972 | B62: =SUM(B2:B61) -> 19.797729 | C62: =SUM(C2:C61) -> 24.758363 | D62: =SUM(D2:D61) -> 19.790531 | E62: =SUM(E2:E61) -> 19.79768 | F62: =SUM(F2:F61) -> 22.76462 | G62: =SUM(G2:G61) -> 26.724111 | H62: =SUM(H2:H61) -> 27.706845 | ... T62: =SUM(T2:T61) -> 25.795199
